<?xml version="1.0" ?>
<robot name="synkar_robot" xmlns:xacro="http://www.ros.org/wiki/xacro">

<xacro:include filename="$(find synkar_robot_description)/urdf/materials.xacro" />
<xacro:include filename="$(find synkar_robot_description)/urdf/synkar_robot.trans" />
<xacro:include filename="$(find synkar_robot_description)/urdf/synkar_robot.gazebo" />
<link name="base_link">
  <inertial>
    <origin xyz="9.276950407566456e-16 7.823390100972366e-06 0.18360480308889404" rpy="0 0 0"/>
    <mass value="591.0521687791345"/>
    <inertia ixx="22.256446" iyy="15.442645" izz="27.027958" ixy="0.0" iyz="0.000618" ixz="0.0"/>
  </inertial>
  <visual>
    <origin xyz="0 0 0" rpy="0 0 0"/>
    <geometry>
      <mesh filename="package://synkar_robot_description/meshes/base_link.stl" scale="0.001 0.001 0.001"/>
    </geometry>
    <material name="silver"/>
  </visual>
  <collision>
    <origin xyz="0 0 0" rpy="0 0 0"/>
    <geometry>
      <mesh filename="package://synkar_robot_description/meshes/base_link.stl" scale="0.001 0.001 0.001"/>
    </geometry>
  </collision>
</link>

<link name="roda_v1_1">
  <inertial>
    <origin xyz="0.0224999999999983 5.551115123125783e-17 0.0" rpy="0 0 0"/>
    <mass value="7.553355760718545"/>
    <inertia ixx="0.025705" iyy="0.014127" izz="0.014127" ixy="-0.0" iyz="0.0" ixz="0.0"/>
  </inertial>
  <visual>
    <origin xyz="-0.15 0.16 -0.05" rpy="0 0 0"/>
    <geometry>
      <mesh filename="package://synkar_robot_description/meshes/roda_v2__3__1.stl" scale="0.001 0.001 0.001"/>
    </geometry>
    <material name="silver"/>
  </visual>
  <collision>
    <origin xyz="-0.15 0.16 -0.05" rpy="0 0 0"/>
    <geometry>
      <mesh filename="package://synkar_robot_description/meshes/roda_v2__3__1.stl" scale="0.001 0.001 0.001"/>
    </geometry>
  </collision>
</link>

<link name="roda_v1__1__1">
  <inertial>
    <origin xyz="0.022499999999998438 1.1102230246251565e-16 0.0" rpy="0 0 0"/>
    <mass value="7.553355760718545"/>
    <inertia ixx="0.025705" iyy="0.014127" izz="0.014127" ixy="0.0" iyz="0.0" ixz="0.0"/>
  </inertial>
  <visual>
    <origin xyz="-0.15 -0.19 -0.05" rpy="0 0 0"/>
    <geometry>
      <mesh filename="package://synkar_robot_description/meshes/roda_v2_1.stl" scale="0.001 0.001 0.001"/>
    </geometry>
    <material name="silver"/>
  </visual>
  <collision>
    <origin xyz="-0.15 -0.19 -0.05" rpy="0 0 0"/>
    <geometry>
      <mesh filename="package://synkar_robot_description/meshes/roda_v2_1.stl" scale="0.001 0.001 0.001"/>
    </geometry>
  </collision>
</link>

<link name="roda_v1__2__1">
  <inertial>
    <origin xyz="-0.022499999999998438 1.1102230246251565e-16 0.0" rpy="0 0 0"/>
    <mass value="7.553355760718545"/>
    <inertia ixx="0.025705" iyy="0.014127" izz="0.014127" ixy="0.0" iyz="0.0" ixz="0.0"/>
  </inertial>
  <visual>
    <origin xyz="0.15 -0.19 -0.05" rpy="0 0 0"/>
    <geometry>
      <mesh filename="package://synkar_robot_description/meshes/roda_v2__2__1.stl" scale="0.001 0.001 0.001"/>
    </geometry>
    <material name="silver"/>
  </visual>
  <collision>
    <origin xyz="0.15 -0.19 -0.05" rpy="0 0 0"/>
    <geometry>
      <mesh filename="package://synkar_robot_description/meshes/roda_v2__2__1.stl" scale="0.001 0.001 0.001"/>
    </geometry>
  </collision>
</link>

<link name="roda_v1__3__1">
  <inertial>
    <origin xyz="-0.0224999999999983 5.551115123125783e-17 0.0" rpy="0 0 0"/>
    <mass value="7.553355760718545"/>
    <inertia ixx="0.025705" iyy="0.014127" izz="0.014127" ixy="0.0" iyz="-0.0" ixz="0.0"/>
  </inertial>
  <visual>
    <origin xyz="0.15 0.16 -0.05" rpy="0 0 0"/>
    <geometry>
      <mesh filename="package://synkar_robot_description/meshes/roda_v2__1__1.stl" scale="0.001 0.001 0.001"/>
    </geometry>
    <material name="silver"/>
  </visual>
  <collision>
    <origin xyz="0.15 0.16 -0.05" rpy="0 0 0"/>
    <geometry>
      <mesh filename="package://synkar_robot_description/meshes/roda_v2__1__1.stl" scale="0.001 0.001 0.001"/>
    </geometry>
  </collision>
</link>

<joint name="Revolucionar_1" type="continuous">
  <origin xyz="0.15 -0.16 0.05" rpy="0 0 0"/>
  <parent link="base_link"/>
  <child link="roda_v1_1"/>
  <axis xyz="-1.0 0.0 0.0"/>
</joint>

<joint name="Revolucionar_2" type="continuous">
  <origin xyz="0.15 0.19 0.05" rpy="0 0 0"/>
  <parent link="base_link"/>
  <child link="roda_v1__1__1"/>
  <axis xyz="-1.0 0.0 0.0"/>
</joint>

<joint name="Revolucionar_3" type="continuous">
  <origin xyz="-0.15 0.19 0.05" rpy="0 0 0"/>
  <parent link="base_link"/>
  <child link="roda_v1__2__1"/>
  <axis xyz="-1.0 0.0 0.0"/>
</joint>

<joint name="Revolucionar_4" type="continuous">
  <origin xyz="-0.15 -0.16 0.05" rpy="0 0 0"/>
  <parent link="base_link"/>
  <child link="roda_v1__3__1"/>
  <axis xyz="-1.0 0.0 0.0"/>
</joint>


  <!-- ========== T265 (mono) ========== -->
  <link name="camera_t265_link"/>
  <joint name="camera_t265_joint" type="fixed">
    <parent link="base_link"/>
    <child  link="camera_t265_link"/>
    <!-- x=0.290, y=0.2425, z=ajuste -->
    <origin xyz="0.290 0.2425 0.20" rpy="0 0 0"/>
  </joint>

  <gazebo reference="camera_t265_link">
    <sensor name="t265_cam" type="camera">
      <camera name="mono">
        <horizontal_fov>1.047</horizontal_fov>
        <image>
          <width>480</width><height>480</height><format>R8G8B8</format>
        </image>
        <clip><near>0.05</near><far>20.0</far></clip>
      </camera>
      <plugin name="gazebo_ros_camera" filename="libgazebo_ros_camera.so">
        <frameName>camera_t265_link</frameName>
        <imageTopicName>/camera/t265/image_raw</imageTopicName>
        <cameraInfoTopicName>/camera/t265/camera_info</cameraInfoTopicName>
        <updateRate>30.0</updateRate>
      </plugin>
    </sensor>
  </gazebo>

  <!-- ========== D435i (RGB + Depth) ========== -->
  <link name="camera_d435i_link"/>
  <joint name="camera_d435i_joint" type="fixed">
    <parent link="base_link"/>
    <child  link="camera_d435i_link"/>
    <!-- x=0.290, y=0.2725, z=ajuste -->
    <origin xyz="0.290 0.2725 0.20" rpy="0 0 0"/>
  </joint>

  <!-- RGB -->
  <gazebo reference="camera_d435i_link">
    <sensor name="d435i_rgb" type="camera">
      <camera name="rgb">
        <horizontal_fov>1.047</horizontal_fov>
        <image>
          <width>640</width><height>480</height><format>R8G8B8</format>
        </image>
        <clip><near>0.1</near><far>10.0</far></clip>
      </camera>
      <plugin name="gazebo_ros_camera" filename="libgazebo_ros_camera.so">
        <frameName>camera_d435i_link</frameName>
        <imageTopicName>/camera/d435i/image_raw</imageTopicName>
        <cameraInfoTopicName>/camera/d435i/camera_info</cameraInfoTopicName>
        <updateRate>30.0</updateRate>
      </plugin>
    </sensor>
  </gazebo>

  <!-- Depth + PointCloud -->
  <gazebo reference="camera_d435i_link">
    <sensor name="d435i_depth" type="depth">
      <camera name="depth">
        <horizontal_fov>1.047</horizontal_fov>
        <image>
          <width>640</width><height>480</height><format>R8G8B8</format>
        </image>
        <clip><near>0.1</near><far>10.0</far></clip>
      </camera>
      <plugin name="gazebo_ros_depth_camera" filename="libgazebo_ros_depth_camera.so">
        <frameName>camera_d435i_link</frameName>
        <depthImageTopicName>/camera/d435i/image_raw</depthImageTopicName>
        <cameraInfoTopicName>/camera/d435i/camera_info</cameraInfoTopicName>
        <pointCloudTopicName>/camera/d435i/points</pointCloudTopicName>
        <updateRate>30.0</updateRate>
      </plugin>
    </sensor>
  </gazebo>

</robot>
